2022-10-14 13:55:27,471 DEBUG    root            Loaded Command Group: ['gcloud', 'config']
2022-10-14 13:55:27,492 DEBUG    root            Loaded Command Group: ['gcloud', 'config', 'set']
2022-10-14 13:55:27,494 DEBUG    root            Running [gcloud.config.set] with arguments: [SECTION/PROPERTY: "compute/zone", VALUE: "europe-west1-b"]
2022-10-14 13:55:27,503 DEBUG    root            (gcloud.config.set) You do not currently have an active account selected.
Please run:

  $ gcloud auth login

to obtain new credentials.

If you have already logged in with a different account:

    $ gcloud config set account ACCOUNT

to select an already authenticated account to use.
Traceback (most recent call last):
  File "/Users/ledemn/Desktop/google-cloud-sdk/lib/googlecloudsdk/calliope/cli.py", line 987, in Execute
    resources = calliope_command.Run(cli=self, args=args)
  File "/Users/ledemn/Desktop/google-cloud-sdk/lib/googlecloudsdk/calliope/backend.py", line 807, in Run
    resources = command_instance.Run(args)
  File "/Users/ledemn/Desktop/google-cloud-sdk/lib/surface/config/set.py", line 130, in Run
    args.value, zonal=True)
  File "/Users/ledemn/Desktop/google-cloud-sdk/lib/googlecloudsdk/command_lib/config/config_validators.py", line 42, in WarnIfSettingNonExistentRegionZone
    client = holder.client
  File "/Users/ledemn/Desktop/google-cloud-sdk/lib/googlecloudsdk/api_lib/compute/base_classes.py", line 68, in client
    self._api_version, self._no_http)
  File "/Users/ledemn/Desktop/google-cloud-sdk/lib/googlecloudsdk/api_lib/compute/client_adapter.py", line 56, in __init__
    self._API_NAME, self._api_version, no_http=no_http)
  File "/Users/ledemn/Desktop/google-cloud-sdk/lib/googlecloudsdk/api_lib/util/apis.py", line 267, in GetClientInstance
    http_timeout_sec=http_timeout_sec)
  File "/Users/ledemn/Desktop/google-cloud-sdk/lib/googlecloudsdk/api_lib/util/apis_internal.py", line 172, in _GetClientInstance
    timeout=http_timeout_sec if http_timeout_sec else 'unset')
  File "/Users/ledemn/Desktop/google-cloud-sdk/lib/googlecloudsdk/core/credentials/transports.py", line 86, in GetApitoolsTransport
    redact_request_body_reason=redact_request_body_reason)
  File "/Users/ledemn/Desktop/google-cloud-sdk/lib/googlecloudsdk/core/credentials/requests.py", line 82, in GetSession
    allow_account_impersonation, True)
  File "/Users/ledemn/Desktop/google-cloud-sdk/lib/googlecloudsdk/core/credentials/requests.py", line 126, in WrapQuota
    use_google_auth)
  File "/Users/ledemn/Desktop/google-cloud-sdk/lib/googlecloudsdk/core/credentials/transport.py", line 54, in QuotaProject
    creds = store.LoadIfEnabled(allow_account_impersonation, use_google_auth)
  File "/Users/ledemn/Desktop/google-cloud-sdk/lib/googlecloudsdk/core/credentials/store.py", line 456, in LoadIfEnabled
    use_google_auth=use_google_auth)
  File "/Users/ledemn/Desktop/google-cloud-sdk/lib/googlecloudsdk/core/credentials/store.py", line 569, in Load
    with_access_token_cache=with_access_token_cache)
  File "/Users/ledemn/Desktop/google-cloud-sdk/lib/googlecloudsdk/core/credentials/store.py", line 720, in _Load
    named_configs.ActiveConfig(False).file_path)
googlecloudsdk.core.credentials.exceptions.NoActiveAccountException: You do not currently have an active account selected.
Please run:

  $ gcloud auth login

to obtain new credentials.

If you have already logged in with a different account:

    $ gcloud config set account ACCOUNT

to select an already authenticated account to use.
2022-10-14 13:55:27,505 ERROR    root            (gcloud.config.set) You do not currently have an active account selected.
Please run:

  $ gcloud auth login

to obtain new credentials.

If you have already logged in with a different account:

    $ gcloud config set account ACCOUNT

to select an already authenticated account to use.
